<?xml version="1.0" encoding="UTF-8"?>
<testng-results skipped="0" failed="1" ignored="0" total="2" passed="1">
  <reporter-output>
    <line>
      <![CDATA[Default test : Started]]>
    </line>
    <line>
      <![CDATA[m1 : Starting]]>
    </line>
    <line>
      <![CDATA[m1 : FAILED]]>
    </line>
    <line>
      <![CDATA[m2 : Starting]]>
    </line>
    <line>
      <![CDATA[m2 : PASS]]>
    </line>
  </reporter-output>
  <suite name="Default suite" duration-ms="161" started-at="2018-06-10T22:21:08Z" finished-at="2018-06-10T22:21:08Z">
    <groups>
    </groups>
    <test name="Default test" duration-ms="161" started-at="2018-06-10T22:21:08Z" finished-at="2018-06-10T22:21:08Z">
      <class name="com.listener123.Test2">
        <test-method status="FAIL" signature="m1()[pri:0, instance:com.listener123.Test2@215be6bb]" name="m1" duration-ms="44" started-at="2018-06-10T11:21:08Z" finished-at="2018-06-10T11:21:08Z">
          <exception class="java.lang.AssertionError">
            <message>
              <![CDATA[expected [true] but found [false]]]>
            </message>
            <full-stacktrace>
              <![CDATA[java.lang.AssertionError: expected [true] but found [false]
	at org.testng.Assert.fail(Assert.java:93)
	at org.testng.Assert.failNotEquals(Assert.java:512)
	at org.testng.Assert.assertTrue(Assert.java:41)
	at org.testng.Assert.assertTrue(Assert.java:51)
	at com.listener123.Test2.m1(Test2.java:14)
	at sun.reflect.NativeMethodAccessorImpl.invoke0(Native Method)
	at sun.reflect.NativeMethodAccessorImpl.invoke(Unknown Source)
	at sun.reflect.DelegatingMethodAccessorImpl.invoke(Unknown Source)
	at java.lang.reflect.Method.invoke(Unknown Source)
	at org.testng.internal.MethodInvocationHelper.invokeMethod(MethodInvocationHelper.java:108)
	at org.testng.internal.Invoker.invokeMethod(Invoker.java:669)
	at org.testng.internal.Invoker.invokeTestMethod(Invoker.java:877)
	at org.testng.internal.Invoker.invokeTestMethods(Invoker.java:1201)
	at org.testng.internal.TestMethodWorker.invokeTestMethods(TestMethodWorker.java:125)
	at org.testng.internal.TestMethodWorker.run(TestMethodWorker.java:109)
	at org.testng.TestRunner.privateRun(TestRunner.java:776)
	at org.testng.TestRunner.run(TestRunner.java:634)
	at org.testng.SuiteRunner.runTest(SuiteRunner.java:425)
	at org.testng.SuiteRunner.runSequentially(SuiteRunner.java:420)
	at org.testng.SuiteRunner.privateRun(SuiteRunner.java:385)
	at org.testng.SuiteRunner.run(SuiteRunner.java:334)
	at org.testng.SuiteRunnerWorker.runSuite(SuiteRunnerWorker.java:52)
	at org.testng.SuiteRunnerWorker.run(SuiteRunnerWorker.java:86)
	at org.testng.TestNG.runSuitesSequentially(TestNG.java:1318)
	at org.testng.TestNG.runSuitesLocally(TestNG.java:1243)
	at org.testng.TestNG.runSuites(TestNG.java:1161)
	at org.testng.TestNG.run(TestNG.java:1129)
	at org.testng.remote.AbstractRemoteTestNG.run(AbstractRemoteTestNG.java:114)
	at org.testng.remote.RemoteTestNG.initAndRun(RemoteTestNG.java:251)
	at org.testng.remote.RemoteTestNG.main(RemoteTestNG.java:77)
]]>
            </full-stacktrace>
          </exception> <!-- java.lang.AssertionError -->
          <reporter-output>
            <line>
              <![CDATA[m1 : Starting]]>
            </line>
            <line>
              <![CDATA[m1 : FAILED]]>
            </line>
          </reporter-output>
        </test-method> <!-- m1 -->
        <test-method status="PASS" signature="m2()[pri:0, instance:com.listener123.Test2@215be6bb]" name="m2" duration-ms="22" started-at="2018-06-10T11:21:08Z" finished-at="2018-06-10T11:21:08Z">
          <reporter-output>
            <line>
              <![CDATA[m2 : Starting]]>
            </line>
            <line>
              <![CDATA[m2 : PASS]]>
            </line>
          </reporter-output>
        </test-method> <!-- m2 -->
      </class> <!-- com.listener123.Test2 -->
    </test> <!-- Default test -->
  </suite> <!-- Default suite -->
</testng-results>
